<mujoco model="reacher">
    <include file="./common/skybox.xml"/>
    <include file="./common/materials.xml"/>
    <include file="./common/visual.xml"/>

    <compiler angle="radian" inertiafromgeom="true" meshdir="../meshes" />
    <option gravity="0 0 -9.81" integrator="RK4" timestep="0.01"/>
    <default>
        <joint armature="1" damping="1" limited="true"/>
        <geom contype="0" friction="1 0.1 0.1"/>
        <default class="ground">
            <geom material="grid" type="plane" contype="0" conaffinity="0"/>
        </default>
        <default class="link">
            <geom contype="1" conaffinity="1" fromto="0 0 0 0.1 0 0" rgba="0.0 0.4 0.6 1" size=".01" type="capsule" />
        </default>
    </default>

    <worldbody>
        <!-- Arena -->
        <light cutoff="100" diffuse="0.05 0.05 0.05" dir="0 -0.5 -2.0" directional="true" exponent="1" pos="0 0.5 2.0" specular=".1 .1 .1" />
        <geom name="ground" class="ground" pos="0 0 0" size="5 5 1"/>
        <camera name="cam0" pos="-0.1 0.1 0.0" quat="0.707 0.707 0 0" />
        <!--
        <geom conaffinity="0" contype="0" name="ground" pos="0 0 0" rgba="0.9 0.9 0.9 1" size="1 1 10" type="plane"/>
        -->
        <!-- Arm -->
        <geom conaffinity="0" contype="0" fromto="0 0 0 0 0 0.05" name="root" rgba="0.9 0.4 0.6 1" size=".011" type="cylinder"/>
        <body name="body0" pos="0 0 .02">
            <geom class='link' name='link0'/>
            <joint axis="0 0 1" limited="false" name="joint0" pos="0 0 0" type="hinge"/>
            <body name="body1" pos="0.1 0 0">
                <joint axis="0 0 1" limited="true" name="joint1" pos="0 0 0" range="-3.0 3.0" type="hinge"/>
                <geom class='link' name='link1'/>
                <body name="body2" pos="0.1 0 0">
                    <joint axis="0 0 1" limited="true" name="joint2" pos="0 0 0" range="-3.0 3.0" type="hinge"/>
                    <geom class='link' name='link2'/>
                    <body name="body3" pos="0.1 0 0">
                        <joint axis="0 0 1" limited="true" name="joint3" pos="0 0 0" range="-3.0 3.0" type="hinge"/>
                        <geom class='link' name='link3'/>
                        <body name="body4" pos="0.1 0 0">
                            <joint axis="0 0 1" limited="true" name="joint4" pos="0 0 0" range="-3.0 3.0" type="hinge"/>
                            <geom class='link' name='link4'/>
                            <body name="body5" pos="0.1 0 0">
                                <joint axis="0 0 1" limited="true" name="joint5" pos="0 0 0" range="-3.0 3.0" type="hinge"/>
                                <geom class='link' name='link5'/>
                                <body name="body6" pos="0.1 0 0">
                                    <joint axis="0 0 1" limited="true" name="joint6" pos="0 0 0" range="-3.0 3.0" type="hinge"/>
                                    <geom class='link' name='link6'/>
                                    <body name="fingertip" pos="0.11 0 0">
                                        <geom contype="1" conaffinity="1" name="fingertip" pos="0 0 0" rgba="0.0 0.8 0.6 1" size=".01" type="sphere"/>
                                        <site name='fingertip' />
                                            <!--<geom fromto="0 -0.02 0 0 0.02 0" contype="1" conaffinity="1" name="fingertip0" pos="0 0 0" rgba="0.0 0.4 0.6 1" size=".01" type="capsule"/>
                                            <geom fromto="0 -0.02 0 0.02 -0.02 0" contype="1" conaffinity="1" name="fingertip1" pos="0 0 0" rgba="0.0 0.4 0.6 1" size=".01" type="capsule"/>
                                            <geom fromto="0 0.02 0 0.02 0.02 0" contype="1" conaffinity="1" name="fingertip2" pos="0 0 0" rgba="0.0 0.4 0.6 1" size=".01" type="capsule"/> -->
                                    </body>
                                </body>
                            </body>
                        </body>
                    </body>
                </body>
            </body>
        </body>

        <body name="target" pos=".1 -.1 .01">
            <joint armature="0" axis="1 0 0" damping="0" limited="true" name="target_x" pos="0 0 0" range="-.4 .4" ref=".1" stiffness="0" type="slide"/>
            <joint armature="0" axis="0 1 0" damping="0" limited="true" name="target_y" pos="0 0 0" range="-.4 .4" ref="-.1" stiffness="0" type="slide"/>
            <geom conaffinity="0" contype="0" name="target" pos="0 0 0" rgba="0.9 0.2 0.2 1" size=".020 .001 .002" type="cylinder"/>
        </body>
    </worldbody>

    <actuator>
        <velocity ctrllimited="true" ctrlrange="-1.0 1.0" gear="1" joint="joint0"/>
        <velocity ctrllimited="true" ctrlrange="-1.0 1.0" gear="1" joint="joint1"/>
        <velocity ctrllimited="true" ctrlrange="-1.0 1.0" gear="1" joint="joint2"/>
        <velocity ctrllimited="true" ctrlrange="-1.0 1.0" gear="1" joint="joint3"/>
        <velocity ctrllimited="true" ctrlrange="-1.0 1.0" gear="1" joint="joint4"/>
        <velocity ctrllimited="true" ctrlrange="-1.0 1.0" gear="1" joint="joint5"/>
        <velocity ctrllimited="true" ctrlrange="-1.0 1.0" gear="1" joint="joint6"/>
    </actuator>
</mujoco>

