<mujoco model="sawyer_lift">
    <include file="./common/sawyer.xml" />
    <default>
        <default class="obstacle">
            <geom conaffinity="1" contype="1" pos="0 0 0" rgba="0.55 0.25 0.07 1" type="capsule" size="0.025"/>
        </default>
    </default>
    <worldbody>
        <body name="table" pos="0.66 -0.5 0.41">
          <geom friction="1 0.005 0.0001" name="table_collision" pos="0 0 0" size="0.4 0.4 0.41" type="box" />
          <geom conaffinity="0" contype="0" group="1" name="table_visual" pos="0 0 0" size="0.4 0.4 0.41" type="box" />
          <site name="table_top" pos="0.0 0.0 0.41" rgba="0 0 0 0" size="0.001 0.001 0.001" />
      </body>

        <body name="obstacle" pos="0.40 0.3 0.8">
            <geom class="obstacle" name="obstacle0_geom" fromto="0.1 0.60 0.0 0.1 0.60 0.4" /> <!--right-->
            <geom class="obstacle" name="obstacle1_geom" fromto="0.1 -0.15 0.0 0.1 -0.15 0.4" /> <!--center-->
            <geom class="obstacle" name="obstacle2_geom" fromto="0.1 -0.15 0.4 0.1 0.60 0.4" /> <!--up -->
            <geom class="obstacle" name="obstacle3_geom" fromto="0.1 -0.15 0.0 0.1 0.60 0.0" /> <!--bottom -->
            <!-- <geom class="obstacle" name="obstacle4_geom" fromto="0.1 0.55 &#45;0.9 0.1 0.55 0.4" /> <!&#45;&#45;most right &#45;&#45;> -->
            <!-- <geom class="obstacle" name="obstacle5_geom" fromto="0.1 &#45;0.25 &#45;0.9 0.1 &#45;0.25 &#45;0.55" /> <!&#45;&#45;left &#45;&#45;> -->
            <!-- <geom class="obstacle" name="obstacle6_geom" fromto="0.1 &#45;0.25 &#45;0.55 0.1 0.15 &#45;0.55" /> <!&#45;&#45;left &#45;&#45;> -->
            <!-- <geom class="obstacle" rgba="0.6 0.6 0.6 0.7" name="obstacle7_geom" pos="&#45;0.8 &#45;0.3 &#45;0.4" size="0.01 1.4 1.0" type='box'/> <!&#45;&#45;left &#45;&#45;> -->
        </body>

        <body name="cube" pos="0.45 -0.7 0.86" quat="0.8775825618903728 0 0 0.479425538604203">
                <!-- <geom density="400" friction="4.0 0.005 0.0001" group="1" name="cube" pos="0 0 0" rgba="1 0 0 1" size="0.04 0.04 0.04" type="box" /> -->
            <inertial pos="0 0 0" mass="0.01" diaginertia="100000 100000 100000"/>
            <geom contype="1" conaffinity="1" friction="2.0 0.005 0.0001" condim="4" group="1" name="cube" pos="0 0 0" rgba="1 0 0 1" size="0.04 0.04 0.04" type="box" solimp="0.99 0.99 0.01" solref="0.01 1"/>
            <site name="cube" pos="0 0 0" rgba="1 0 0 1" size="0.002 0.002 0.002" type="sphere" />
            <joint name="cube" type="free" />
        </body>
        <body name="target" pos="0.56 -0.4 0.82">
            <joint armature="0" axis="1 0 0" damping="0" limited="true" name="target_x" pos="0 0 0" range="0. .6" stiffness="0" ref="0.56" type="slide"/>
            <joint armature="0" axis="0 1 0" damping="0" limited="true" name="target_y" pos="0 0 0" range="-.6 .6" stiffness="0" ref="-0.4" type="slide"/>
            <geom conaffinity="0" contype="0" group="0" name="target" pos="0 0 0" rgba="0.2 0.8 0.2 1" size=".030 .001 .001" type="cylinder"/>
        </body>
    </worldbody>
</mujoco>
