<mujoco model="sawyer_lift">
    <include file="./common/sawyer.xml" />
    <default>
    </default>
      <asset>
    <texture file="../textures/light-wood.png" type="2d" name="tex-light-wood"/>
    <texture file="../textures/dark-wood.png" type="2d" name="tex-dark-wood"/>
    <material name="light-wood" reflectance="0.5" texrepeat="15 15" texture="tex-light-wood" texuniform="true"/>
    <material name="dark-wood" reflectance="0.5" texrepeat="5 5" texture="tex-dark-wood" texuniform="true"/>
  </asset>
    <worldbody>
    <body name="table" pos="0.9 0.0 0.8">
        <geom pos="0 0 0" size="0.4 0.4 0.02" type="box" friction="1 0.005 0.0001"/>
        <geom pos="0 0 0" material="light-wood" size="0.4 0.4 0.02" type="box" conaffinity="0" contype="0" group="1"/>
        <geom pos="0.38 0.38 -0.4" size="0.02 0.4 0.08" type="cylinder" friction="1 0.005 0.0001" rgba="0 0 1 1" />
        <geom pos="0.38 0.38 -0.4" size="0.02 0.4 0.08" type="cylinder" conaffinity="0" contype="0" group="1" material="light-wood"/>
        <geom pos="-0.38 -0.38 -0.4" size="0.02 0.4 0.08" type="cylinder" friction="1 0.005 0.0001" rgba="0 0 1 1" />
        <geom pos="-0.38 -0.38 -0.4" size="0.02 0.4 0.08" type="cylinder" conaffinity="0" contype="0" group="1" material="light-wood"/>
        <geom pos="-0.38 0.38 -0.4" size="0.02 0.4 0.08" type="cylinder" friction="1 0.005 0.0001" rgba="0 0 1 1" />
        <geom pos="-0.38 0.38 -0.4" size="0.02 0.4 0.08" type="cylinder" conaffinity="0" contype="0" group="1" material="light-wood"/>
        <geom pos="0.38 -0.38 -0.4" size="0.02 0.4 0.08" type="cylinder" friction="1 0.005 0.0001" rgba="0 0 1 1" />
        <geom pos="0.38 -0.38 -0.4" size="0.02 0.4 0.08" type="cylinder" conaffinity="0" contype="0" group="1" material="light-wood"/>
    </body>

    <body name="bin1" pos="0.9 0.0 1.01" quat="0 1 0 1">
        <geom friction="1 0.005 0.0001" pos="0 0.15 0.05" rgba="0 0 1 1" size="0.18 0.01 0.2" type="box" />
        <geom conaffinity="0" contype="0" group="1" material="dark-wood" pos="0 0.15 0.05" size="0.18 0.01 0.2" type="box" />
        <geom friction="1 0.005 0.0001" pos="0 -0.15 0.05" rgba="0 0 1 1" size="0.18 0.01 0.2" type="box" />
        <geom conaffinity="0" contype="0" group="1" material="dark-wood" pos="0 -0.15 0.05" size="0.18 0.01 0.2" type="box" />
        <geom friction="1 0.005 0.0001" pos="0.17 0 0.05" rgba="0 0 1 1" size="0.01 0.15 0.2" type="box" />
        <geom conaffinity="0" contype="0" group="1" material="dark-wood" pos="0.17 0 0.05" size="0.01 0.15 0.2" type="box" />
        <geom friction="1 0.005 0.0001" pos="-0.17 0 0.05" rgba="0 0 1 1" size="0.01 0.15 0.2" type="box" />
        <geom conaffinity="0" contype="0" group="1" material="dark-wood" pos="-0.17 0 0.05" size="0.01 0.15 0.2" type="box" />
    </body>

        <body name="cube" pos="0.9 -0.023869616735809365 0.9">
            <inertial pos="0 0 0" mass="0.01" diaginertia="100000 100000 100000"/>
            <geom contype="1" conaffinity="1" friction="2.0 0.005 0.0001" condim="4" group="1" name="cube" pos="0 0 0" rgba="1 0 0 1" size="0.04 0.04 0.04" type="box" solimp="0.99 0.99 0.01" solref="0.01 1"/>
            <site name="cube" pos="0 0 0" rgba="1 0 0 1" size="0.002 0.002 0.002" type="sphere" />
            <joint name="cube" type="free" />
        </body>
        <body name="target" pos="1.1 0.0 0.85">
            <joint armature="0" axis="1 0 0" damping="0" limited="true" name="target_x" pos="0 0 0" range="-.3 .3" stiffness="0" type="slide"/>
            <joint armature="0" axis="0 1 0" damping="0" limited="true" name="target_y" pos="0 0 0" range="-.3 .3" stiffness="0" type="slide"/>
            <geom conaffinity="0" contype="0" group="0" name="target" pos="0 0 0" rgba="0.2 0.8 0.2 1" size=".030 .001 .001" type="cylinder"/>
        </body>
    </worldbody>
</mujoco>
