<mujoco model="sawyer_reach_obstacle">
    <include file="./common/sawyer.xml" />
    <default>
        <default class="obstacle">
            <geom conaffinity="1" contype="0" pos="0 0 0" rgba="0.55 0.25 0.07 1" />
        </default>
    </default>
    <worldbody>
        <body name="table" pos="0.56 0.0 0.41">
          <geom friction="1 0.005 0.0001" name="table_collision" pos="0 0 0" size="0.4 0.4 0.41" type="box" />
          <geom conaffinity="0" contype="0" group="1" name="table_visual" pos="0 0 0" size="0.4 0.4 0.41" type="box" />
          <site name="table_top" pos="0.0 0.0 0.41" rgba="0 0 0 0" size="0.001 0.001 0.001" />
        </body>

        <body name="obstacle1" pos="0.7100000000000001 0.25 0.4">
            <geom class="obstacle" name="obstacle1_geom" size="0.03 1.2" type="cylinder" />
        </body>
        <body name="obstacle2" pos="0.41000000000000003 -0.15 0.4">
            <geom class="obstacle" name="obstacle2_geom" size="0.03 1.2" type="cylinder" />
        </body>
        <body name="obstacle3" pos="0.7100000000000001 -0.2 0.4">
            <geom class="obstacle" name="obstacle3_geom" size="0.03 1.2" type="cylinder" />
        </body>
        <body name="obstacle4" pos="0.31000000000000005 0.25 0.4">
            <geom class="obstacle" name="obstacle4_geom" size="0.03 1.2" type="cylinder" />
        </body>
        <body name="target" pos="0.6 0.0 1.2">
            <joint axis="1 0 0" limited="true" name="target_x" pos="0 0 0" range="-1 1" ref="0.6" type="slide" />
            <joint axis="0 1 0" limited="true" name="target_y" pos="0 0 0" range="-1 1" ref="0" type="slide" />
            <joint axis="0 0 1" limited="true" name="target_z" pos="0 0 0" range="-1 1.5" ref="1.2" type="slide" />
            <geom conaffinity="0" contype="0" group="1" name="target_geom" pos="0 0 0" rgba="0 1 0 0.5" size="0.02" type="sphere" />
        </body>
    </worldbody>
</mujoco>
