<mujocoinclude>
<!-- ======================================================
    Model 		:: Sawyer (MuJoCoV2.0)
    Author      :: Vikash Kumar
        Contacts 	: vikashplus@gmail.com
        Last edits 	: 3Apr'20, 25Aug'18
    Copyright 2018 Vikash Kumar
        Licensed under Apache License, Version 2.0 (the "License"); you may not use this file except in compliance with the License. You may obtain a copy of the License at http://www.apache.org/licenses/LICENSE-2.0 Unless required by applicable law or agreed to in writing, software distributed under the License is distributed on an "AS IS" BASIS, WITHOUT WARRANTIES OR CONDITIONS OF ANY KIND, either express or implied. See the License for the specific language governing permissions and limitations under the License.
====================================================== -->
    <!-- <body name="clawGripper_target" pos="0 0 .045" quat="&#45;1 0 1 0"> -->
    <!--     <geom  type="box" size="0.01 0.04 0.01" /> -->
    <!--     <geom size="0.035 0.015" pos="&#45;.024 0 0" type="cylinder" rgba="0.2 0.2 0.2 10" euler="0 1.57 0"/> -->
    <!--  -->
    <!--     <body name="rightclaw_target" pos=".01 .015 0" > -->
    <!--         <geom name="rightclaw_it_target" type="box" pos="0 0.0 0" size="0.05 0.005 0.005"/> -->
    <!--         <joint name="rc_close_target" type="slide" pos="0 0 0" axis="0 &#45;1 0" range="0 .015" user="008" limited="true"/> -->
    <!--     </body> -->
    <!--  -->
    <!--     <body name="leftclaw_target" pos=".01 .02 0"> -->
    <!--         <geom name="leftclaw_it0_target" type="box" pos="0 &#45;.04 0" size="0.05 0.005 0.005"/> -->
    <!--         <joint name="lc_close_target" type="slide" pos="0 0 0" axis="0 1 0" range="0 .015" user="008" limited="true"/> -->
    <!--     </body> -->
    <!-- </body> -->
    <body name="clawGripper_target" pos="0 0 0.0245" quat="0.707105 0 0 0.707108">
        <!-- <geom  type="box" size="0.01 0.04 0.01" /> -->
        <geom size="0.035 0.015" pos="-.0 0 -0.0145" type="cylinder" rgba="0.2 0.2 0.2 0.2"  quat="0.707105 0 0 0.707108"/>
        <geom size="1e-08 5e-09" type="cylinder" />
        <body name="right_gripper_base_target" pos="0 0 0.025">
            <geom quat="0 0 0.707107 0.707107" size="0.029 0.05" type="cylinder" />
            <body name="rightclaw_target" pos="0 0.01 0.02">
                <joint axis="0 -1 0" damping="100" limited="true" name="rc_close_target" pos="0 0 0" range="-0.0115 0.020833" type="slide" />
                <geom conaffinity="0" contype="0" friction="0 0 0" name="l_finger_g0_target" pos="0 0.01725 0.04" quat="0 0 0 -1" size="0.005 0.00675 0.0375" type="box" rgba="0.2 0.2 0.2 0.2"/>
                <geom conaffinity="0" contype="0" friction="0 0 0" name="l_finger_g1_target" pos="-0.005 -0.003 0.0083" quat="0 0 0 -1" size="0.005 0.025 0.0085" type="box" rgba="0.2 0.2 0.2 0.2"/>

                <body name="r_gripper_l_finger_tip_target" pos="0 0.01725 0.075">
                    <geom conaffinity="0" contype="0" friction="0 0 0" name="l_fingertip_g0_target" pos="0 -0.0045 -0.015" quat="0 0 0 1" size="0.004 0.004 0.0185" type="box" rgba="0.2 0.2 0.2 0.2"/>
                </body>
            </body>
            <body name="leftclaw_target" pos="0 -0.01 0.02">
                <joint axis="0 1 0" damping="100" limited="true" name="lc_close_target" pos="0 0 0" range="-0.0115 0.020833"  type="slide" />
                <geom conaffinity="0" contype="0" friction="0 0 0" name="r_finger_g0_target" pos="0 -0.01725 0.04" size="0.005 0.00675 0.0375" type="box" rgba="0.2 0.2 0.2 0.2"/>
                <geom conaffinity="0" contype="0" friction="0 0 0" name="r_finger_g1_target" pos="0.005 0.003 0.0083" size="0.005 0.025 0.0085" type="box" rgba="0.2 0.2 0.2 0.2"/>
                <body name="r_gripper_r_finger_tip_target" pos="0 -0.01725 0.075">
                    <geom conaffinity="0" contype="0" friction="0 0 0" name="r_fingertip_g0_target" pos="0 0.0045 -0.015" size="0.004 0.004 0.0185" type="box" rgba="0.2 0.2 0.2 0.2"/>
                </body>
            </body>
        </body>
    </body>
</mujocoinclude>
