<mujoco model="table_arena">
  <asset>
    <texture builtin="gradient" height="256" rgb1=".9 .9 1." rgb2=".2 .3 .4" type="skybox" width="256"/>
    <texture builtin="checker" height="512" name="texplane" rgb1=".2 .3 .4" rgb2=".1 0.15 0.2" type="2d" width="512"/>
    <material name="floorplane" reflectance="0.5" texrepeat="1 1" texture="texplane" texuniform="true"/>
</asset>

  <default>
    <default class="obstacle">
        <geom conaffinity="1" contype="0" rgba="0.55 0.25 0.07 1" pos="0 0 0" />
    </default>
  </default>

  <worldbody>
    <geom condim="3" material="floorplane" name="floor" pos="0 0 0" size="3 3 .125" type="plane"/>
    <body name="table" pos="0 0 0.4">
      <geom pos="0 0 0" size="0.4 0.4 0.4" type="box" name="table_collision" friction="1 0.005 0.0001"/>
      <geom pos="0 0 0" size="0.4 0.4 0.4" type="box" conaffinity="0" contype="0" group="1" name="table_visual"/>
      <site pos="0 0 0.4" name="table_top" size="0.001 0.001 0.001" rgba="0 0 0 0"/>
    </body>

    <body name="obstacle1" pos="0.15 0.25 0.4">
        <geom name="obstacle1_geom" size="0.02 0.08 0.6" type="box" class="obstacle" />
    </body>
    <body name="obstacle2" pos="-0.15 0.3 0.4">
        <geom name="obstacle2_geom" size="0.07 0.02 0.6" type="box" class="obstacle" />
    </body>
    <body name="obstacle3" pos="0.08 -0.20 0.4">
        <geom name="obstacle3_geom" size="0.02 0.08 0.6" type="box" class="obstacle" />
    </body>
    <body name="obstacle4" pos="-0.4 0.15 0.4">
        <geom name="obstacle4_geom" size="0.02 0.09 0.6" type="box" class="obstacle" />
    </body>
    <body name="obstacle5" pos="-0.4 -0.21 0.4">
        <geom name="obstacle5_geom" size="0.04 0.03 0.6" type="box" class="obstacle" />
    </body>
    <body name="obstacle6" pos="0 -0.25 0.4">
        <geom name="obstacle6_geom" size="0.07 0.03 0.6" type="box" class="obstacle" />
    </body>

    <body name="target" pos=".3 0.1 .4">
        <joint armature="0" axis="1 0 0" damping="0" limited="true" name="target_x" pos="0 0 0" range="-.4 .4" ref=".1" stiffness="0" type="slide"/>
        <joint armature="0" axis="0 1 0" damping="0" limited="true" name="target_y" pos="0 0 0" range="-.4 .4" ref="-.1" stiffness="0" type="slide"/>
        <geom conaffinity="0" contype="0" name="target" pos="0 0 0" rgba="0.9 0.2 0.2 1" size=".04 .401 .04" type="cylinder"/>
    </body>

    <light diffuse=".8 .8 .8" dir="0 -.15 -1" directional="false" pos="1 1 4.0" specular="0.3 0.3 0.3" castshadow="false"/>
    <light diffuse=".8 .8 .8" dir="0 -.15 -1" directional="false" pos="-3. -3. 4.0" specular="0.3 0.3 0.3" castshadow="false"/>
    <!-- front view -->
    <camera mode="fixed" name="frontview" pos="1.6 0 1.45" quat="0.56 0.43 0.43 0.56"/>
    <!-- bird view -->
    <camera mode="fixed" name="birdview" pos="-0.2 0 3.0" quat="0.7071 0 0 0.7071"/>
    <!-- agent view -->
    <camera mode="fixed" name="agentview" pos="0.5 0 1.35" quat="0.653 0.271 0.271 0.653"/>
  </worldbody>
</mujoco>
